Workbook

Sheet 📖 README
A1: 🧺 LAUNDRYHEAP — DATA ANALYSIS WORKBOOK
A2: Synthetic dataset modelled on an on-demand laundry startup | Bangalore, India | Jan 2023 – Dec 2024
A4: 📋 WORKBOOK CONTENTS
A5: Sheet | B5: Description | C5: Rows | D5: Key Column(s) | E5: Notes
A6: 📖 README | B6: Navigation & workbook guide | C6: — | D6: — | E6: You are here
A7: 🔍 Null Audit | B7: Null analysis across all tables | C7: — | D7: — | E7: Start here for data quality check
A8: 📋 Orders | B8: Core fact table — all transactions | C8: 3000 | D8: order_id (PK) | E8: Has 3 FKs: customer_id, rider_id, facility_id
A9: 👤 Customers | B9: Customer master data | C9: 500 | D9: customer_id (PK) | E9: Lookup table for orders
A10: 🚴 Riders | B10: Rider / delivery agent data | C10: 60 | D10: rider_id (PK) | E10: Lookup table for orders
A11: 🏭 Facilities | B11: Laundry facility / processing centers | C11: 8 | D11: facility_id (PK) | E11: Lookup table for orders
A13: 🔗 TABLE RELATIONSHIPS (Schema)
A14: customers (customer_id PK) ──< orders (customer_id FK)
A15: riders (rider_id PK) ──< orders (rider_id FK)
A16: facilities (facility_id PK) ──< orders (facility_id FK)
A18: orders is the FACT TABLE. All 3 dimension tables connect through it.
A20: ⚠️ KNOWN NULLS (Business Logic)
A21: Table | B21: Column | C21: Null Count | D21: Reason / Action
A22: orders | B22: pickup_time | C22: 494 (16.5%) | D22: Cancelled orders — pickup never happened. Valid null. DO NOT fill.
A23: orders | B23: delivery_time | C23: 494 (16.5%) | D23: Cancelled orders — delivery never happened. Valid null. DO NOT fill.
A24: orders | B24: customer_rating | C24: 999 (33.3%) | D24: Cancelled orders + completed orders with no rating given. Flag completed ones.

Sheet 🔍 Null Audit
A1: NULL AUDIT — All Tables
A3: 📊 Summary by Table
A4: Table | B4: Total Rows | C4: Column | D4: Null Count | E4: Null % | F4: Status | G4: Action Required
A5: customers | B5: 500 | C5: ALL COLUMNS | D5: 0 | E5: 0.0% | F5: ✅ Clean | G5: No action needed
A6: riders | B6: 60 | C6: ALL COLUMNS | D6: 0 | E6: 0.0% | F6: ✅ Clean | G6: No action needed
A7: facilities | B7: 8 | C7: ALL COLUMNS | D7: 0 | E7: 0.0% | F7: ✅ Clean | G7: No action needed
A8: orders | B8: 3000 | C8: pickup_time | D8: 494 | E8: 0.165 | F8: ⚠️ Valid Null | G8: Keep null — cancelled orders
A9: orders | B9: 3000 | C9: delivery_time | D9: 494 | E9: 16.5% | F9: ⚠️ Valid Null | G9: Keep null — cancelled orders
A10: orders | B10: 3000 | C10: customer_rating | D10: 999 | E10: 33.3% | F10: 🔴 Review | G10: Cancelled=valid, Completed=flag
A12: ✅ Excel Cleaning Checklist
A13: # | B13: Step | C13: How to do it in Excel
A14: 1 | B14: Check duplicates | C14: orders sheet → select order_id → Data → Remove Duplicates
A15: 2 | B15: Verify null logic | C15: Filter status='Cancelled' → confirm pickup_time & delivery_time are always null
A16: 3 | B16: Flag incomplete ratings | C16: Filter status='Completed' AND customer_rating=blank → these need attention
A17: 4 | B17: Data type check | C17: order_date, pickup_time, delivery_time → must be Date/DateTime not Text
A18: 5 | B18: Verify FK integrity | C18: customer_id in orders must exist in customers sheet (use COUNTIF)
A19: 6 | B19: Review helper column | C19: delivery_duration_hrs in orders sheet — verify formula is correct

Sheet 📋 Orders
A1: order_id | B1: customer_id | C1: rider_id | D1: facility_id | E1: order_date | F1: order_time | G1: service_type | H1: weight_kg | I1: base_price_per_kg | J1: discount_pct | K1: final_amount | L1: payment_method | M1: status | N1: pickup_time | O1: delivery_time | P1: customer_rating | Q1: is_first_order | R1: promo_used | S1: delivery_duration_hrs (helper — formula) | T1: customer_exists | U1: rider_exists | V1: facility_exists
A2: ORD00001 | B2: CUST0251 | C2: RIDER021 | D2: FAC08 | E2: 45118 | F2: 11:26:59 | G2: Ironing | H2: 4.9 | I2: 149 | J2: 0 | K2: 730.1 | L2: Debit Card | M2: Completed | N2: 45118.61 | O2: 45119.488 | P2: 3.9 | Q2: =FALSE() -> FALSE | R2: =FALSE() -> FALSE | S2: =IF(OR(N2="",O2=""),"N/A",ROUND(((O2-N2)*24),1)) -> 21.1 | T2: =COUNTIF('👤 Customers'!$A:$A, B2) -> 1 | U2: =COUNTIF('🚴 Riders'!A1:A61, C2) -> 1 | V2: =COUNTIF('🏭 Facilities'!A1:A9, D2) -> 1
A3: ORD00002 | B3: CUST0149 | C3: RIDER003 | D3: FAC05 | E3: 45150 | F3: 12:46:58 | G3: Wash & Fold | H3: 5 | I3: 199 | J3: 0 | K3: 995 | L3: UPI | M3: Completed | N3: 45150.672 | O3: 45151.747 | P3: 3.4 | Q3: =FALSE() -> FALSE | R3: =FALSE() -> FALSE | S3: =IF(OR(N3="",O3=""),"N/A",ROUND(((O3-N3)*24),1)) -> 25.8 | T3: =COUNTIF('👤 Customers'!$A:$A, B3) -> 1 | U3: =COUNTIF('🚴 Riders'!A2:A62, C3) -> 1 | V3: =COUNTIF('🏭 Facilities'!A2:A10, D3) -> 1
A4: ORD00003 | B4: CUST0301 | C4: RIDER016 | D4: FAC04 | E4: 45299 | F4: 02:41:05 | G4: Dry Clean | H4: 2.4 | I4: 399 | J4: 0 | K4: 957.6 | L4: UPI | M4: Cancelled | Q4: =FALSE() -> FALSE | R4: =FALSE() -> FALSE | S4: =IF(OR(N4="",O4=""),"N/A",ROUND(((O4-N4)*24),1)) -> N/A | T4: =COUNTIF('👤 Customers'!$A:$A, B4) -> 1 | U4: =COUNTIF('🚴 Riders'!A3:A63, C4) -> 1 | V4: =COUNTIF('🏭 Facilities'!A3:A11, D4) -> 1
A5: ORD00004 | B5: CUST0494 | C5: RIDER036 | D5: FAC03 | E5: 45422 | F5: 12:08:55 | G5: Dry Clean | H5: 1.4 | I5: 399 | J5: 0 | K5: 558.6 | L5: Cash | M5: Delayed | N5: 45422.596 | O5: 45423.41 | Q5: =FALSE() -> FALSE | R5: =FALSE() -> FALSE | S5: =IF(OR(N5="",O5=""),"N/A",ROUND(((O5-N5)*24),1)) -> 19.5 | T5: =COUNTIF('👤 Customers'!$A:$A, B5) -> 1 | U5: =COUNTIF('🚴 Riders'!A4:A64, C5) -> 1 | V5: =COUNTIF('🏭 Facilities'!A4:A12, D5) -> 1
A6: ORD00005 | B6: CUST0046 | C6: RIDER042 | D6: FAC04 | E6: 45296 | F6: 11:41:02 | G6: Wash & Iron | H6: 5.6 | I6: 299 | J6: 10 | K6: 1506.96 | L6: Wallet | M6: Completed | N6: 45296.554 | O6: 45297.406 | P6: 4.3 | Q6: =FALSE() -> FALSE | R6: =TRUE() -> TRUE | S6: =IF(OR(N6="",O6=""),"N/A",ROUND(((O6-N6)*24),1)) -> 20.4 | T6: =COUNTIF('👤 Customers'!$A:$A, B6) -> 1 | U6: =COUNTIF('🚴 Riders'!A5:A65, C6) -> 1 | V6: =COUNTIF('🏭 Facilities'!A5:A13, D6) -> 1
A7: ORD00006 | B7: CUST0480 | C7: RIDER048 | D7: FAC05 | E7: 45642 | F7: 17:27:44 | G7: Dry Clean | H7: 3.9 | I7: 399 | J7: 20 | K7: 1244.88 | L7: UPI | M7: Completed | N7: 45642.894 | O7: 45643.524 | P7: 2.5 | Q7: =FALSE() -> FALSE | R7: =TRUE() -> TRUE | S7: =IF(OR(N7="",O7=""),"N/A",ROUND(((O7-N7)*24),1)) -> 15.1 | T7: =COUNTIF('👤 Customers'!$A:$A, B7) -> 1 | U7: =COUNTIF('🚴 Riders'!A6:A66, C7) -> 1 | V7: =COUNTIF('🏭 Facilities'!A6:A14, D7) -> 1
A8: ORD00007 | B8: CUST0240 | C8: RIDER018 | D8: FAC04 | E8: 45187 | F8: 05:38:15 | G8: Ironing | H8: 4.2 | I8: 149 | J8: 10 | K8: 563.22 | L8: UPI | M8: Cancelled | Q8: =FALSE() -> FALSE | R8: =FALSE() -> FALSE | S8: =IF(OR(N8="",O8=""),"N/A",ROUND(((O8-N8)*24),1)) -> N/A | T8: =COUNTIF('👤 Customers'!$A:$A, B8) -> 1 | U8: =COUNTIF('🚴 Riders'!A7:A67, C8) -> 1 | V8: =COUNTIF('🏭 Facilities'!A7:A15, D8) -> 0
A9: ORD00008 | B9: CUST0090 | C9: RIDER040 | D9: FAC07 | E9: 45430 | F9: 12:54:52 | G9: Ironing | H9: 6 | I9: 149 | J9: 0 | K9: 894 | L9: Cash | M9: Completed | N9: 45430.674 | O9: 45431.455 | P9: 3.8 | Q9: =TRUE() -> TRUE | R9: =FALSE() -> FALSE | S9: =IF(OR(N9="",O9=""),"N/A",ROUND(((O9-N9)*24),1)) -> 18.8 | T9: =COUNTIF('👤 Customers'!$A:$A, B9) -> 1 | U9: =COUNTIF('🚴 Riders'!A8:A68, C9) -> 1 | V9: =COUNTIF('🏭 Facilities'!A8:A16, D9) -> 1
A10: ORD00009 | B10: CUST0489 | C10: RIDER022 | D10: FAC05 | E10: 45070 | F10: 12:34:16 | G10: Dry Clean | H10: 4.3 | I10: 399 | J10: 20 | K10: 1372.56 | L10: Wallet | M10: Completed | N10: 45070.583 | O10: 45071.113 | P10: 4.3 | Q10: =TRUE() -> TRUE | R10: =FALSE() -> FALSE | S10: =IF(OR(N10="",O10=""),"N/A",ROUND(((O10-N10)*24),1)) -> 12.7 | T10: =COUNTIF('👤 Customers'!$A:$A, B10) -> 1 | U10: =COUNTIF('🚴 Riders'!A9:A69, C10) -> 1 | V10: =COUNTIF('🏭 Facilities'!A9:A17, D10) -> 0
A11: ORD00010 | B11: CUST0455 | C11: RIDER046 | D11: FAC05 | E11: 45465 | F11: 02:08:33 | G11: Dry Clean | H11: 1.4 | I11: 399 | J11: 0 | K11: 558.6 | L11: UPI | M11: Completed | N11: 45465.133 | O11: 45466.016 | P11: 4.1 | Q11: =FALSE() -> FALSE | R11: =FALSE() -> FALSE | S11: =IF(OR(N11="",O11=""),"N/A",ROUND(((O11-N11)*24),1)) -> 21.2 | T11: =COUNTIF('👤 Customers'!$A:$A, B11) -> 1 | U11: =COUNTIF('🚴 Riders'!A10:A70, C11) -> 1 | V11: =COUNTIF('🏭 Facilities'!A10:A18, D11) -> 0
A12: ORD00011 | B12: CUST0282 | C12: RIDER059 | D12: FAC08 | E12: 45098 | F12: 12:55:41 | G12: Dry Clean | H12: 7.7 | I12: 399 | J12: 0 | K12: 3072.3 | L12: Wallet | M12: Completed | N12: 45098.668 | O12: 45099.449 | P12: 4.5 | Q12: =FALSE() -> FALSE | R12: =FALSE() -> FALSE | S12: =IF(OR(N12="",O12=""),"N/A",ROUND(((O12-N12)*24),1)) -> 18.7 | T12: =COUNTIF('👤 Customers'!$A:$A, B12) -> 1 | U12: =COUNTIF('🚴 Riders'!A11:A71, C12) -> 1 | V12: =COUNTIF('🏭 Facilities'!A11:A19, D12) -> 0
A13: ORD00012 | B13: CUST0058 | C13: RIDER004 | D13: FAC04 | E13: 45455 | F13: 10:29:33 | G13: Premium Care | H13: 7.1 | I13: 599 | J13: 0 | K13: 4252.9 | L13: Wallet | M13: Completed | N13: 45455.535 | O13: 45456.174 | P13: 3.8 | Q13: =FALSE() -> FALSE | R13: =FALSE() -> FALSE | S13: =IF(OR(N13="",O13=""),"N/A",ROUND(((O13-N13)*24),1)) -> 15.4 | T13: =COUNTIF('👤 Customers'!$A:$A, B13) -> 1 | U13: =COUNTIF('🚴 Riders'!A12:A72, C13) -> 0 | V13: =COUNTIF('🏭 Facilities'!A12:A20, D13) -> 0
A14: ORD00013 | B14: CUST0233 | C14: RIDER009 | D14: FAC07 | E14: 45270 | F14: 04:30:17 | G14: Wash & Fold | H14: 5.8 | I14: 199 | J14: 10 | K14: 1038.78 | L14: Cash | M14: Completed | N14: 45270.222 | O14: 45270.963 | P14: 3.9 | Q14: =FALSE() -> FALSE | R14: =FALSE() -> FALSE | S14: =IF(OR(N14="",O14=""),"N/A",ROUND(((O14-N14)*24),1)) -> 17.8 | T14: =COUNTIF('👤 Customers'!$A:$A, B14) -> 1 | U14: =COUNTIF('🚴 Riders'!A13:A73, C14) -> 0 | V14: =COUNTIF('🏭 Facilities'!A13:A21, D14) -> 0
A15: ORD00014 | B15: CUST0359 | C15: RIDER005 | D15: FAC01 | E15: 45166 | F15: 08:41:49 | G15: Wash & Fold | H15: 3.8 | I15: 199 | J15: 20 | K15: 604.96 | L15: UPI | M15: Delayed | N15: 45166.415 | O15: 45166.797 | Q15: =FALSE() -> FALSE | R15: =FALSE() -> FALSE | S15: =IF(OR(N15="",O15=""),"N/A",ROUND(((O15-N15)*24),1)) -> 9.2 | T15: =COUNTIF('👤 Customers'!$A:$A, B15) -> 1 | U15: =COUNTIF('🚴 Riders'!A14:A74, C15) -> 0 | V15: =COUNTIF('🏭 Facilities'!A14:A22, D15) -> 0
A16: ORD00015 | B16: CUST0457 | C16: RIDER025 | D16: FAC08 | E16: 45149 | F16: 23:45:31 | G16: Wash & Iron | H16: 2.3 | I16: 299 | J16: 0 | K16: 687.7 | L16: Cash | M16: Delayed | N16: 45150.153 | O16: 45150.964 | Q16: =FALSE() -> FALSE | R16: =FALSE() -> FALSE | S16: =IF(OR(N16="",O16=""),"N/A",ROUND(((O16-N16)*24),1)) -> 19.5 | T16: =COUNTIF('👤 Customers'!$A:$A, B16) -> 1 | U16: =COUNTIF('🚴 Riders'!A15:A75, C16) -> 1 | V16: =COUNTIF('🏭 Facilities'!A15:A23, D16) -> 0
A17: ORD00016 | B17: CUST0373 | C17: RIDER015 | D17: FAC01 | E17: 45441 | F17: 00:42:25 | G17: Premium Care | H17: 1.9 | I17: 599 | J17: 20 | K17: 910.48 | L17: UPI | M17: Completed | N17: 45441.076 | O17: 45441.815 | P17: 4.9 | Q17: =FALSE() -> FALSE | R17: =FALSE() -> FALSE | S17: =IF(OR(N17="",O17=""),"N/A",ROUND(((O17-N17)*24),1)) -> 17.7 | T17: =COUNTIF('👤 Customers'!$A:$A, B17) -> 1 | U17: =COUNTIF('🚴 Riders'!A16:A76, C17) -> 1 | V17: =COUNTIF('🏭 Facilities'!A16:A24, D17) -> 0
A18: ORD00017 | B18: CUST0372 | C18: RIDER049 | D18: FAC02 | E18: 45256 | F18: 10:19:10 | G18: Premium Care | H18: 3.7 | I18: 599 | J18: 0 | K18: 2216.3 | L18: UPI | M18: Completed | N18: 45256.501 | O18: 45257.078 | P18: 4.5 | Q18: =FALSE() -> FALSE | R18: =FALSE() -> FALSE | S18: =IF(OR(N18="",O18=""),"N/A",ROUND(((O18-N18)*24),1)) -> 13.8 | T18: =COUNTIF('👤 Customers'!$A:$A, B18) -> 1 | U18: =COUNTIF('🚴 Riders'!A17:A77, C18) -> 1 | V18: =COUNTIF('🏭 Facilities'!A17:A25, D18) -> 0
A19: ORD00018 | B19: CUST0025 | C19: RIDER016 | D19: FAC01 | E19: 45613 | F19: 10:25:02 | G19: Wash & Fold | H19: 2.7 | I19: 199 | J19: 0 | K19: 537.3 | L19: Cash | M19: Cancelled | Q19: =FALSE() -> FALSE | R19: =FALSE() -> FALSE | S19: =IF(OR(N19="",O19=""),"N/A",ROUND(((O19-N19)*24),1)) -> N/A | T19: =COUNTIF('👤 Customers'!$A:$A, B19) -> 1 | U19: =COUNTIF('🚴 Riders'!A18:A78, C19) -> 0 | V19: =COUNTIF('🏭 Facilities'!A18:A26, D19) -> 0
A20: ORD00019 | B20: CUST0307 | C20: RIDER050 | D20: FAC06 | E20: 45512 | F20: 22:46:07 | G20: Wash & Fold | H20: 2 | I20: 199 | J20: 30 | K20: 278.6 | L20: Credit Card | M20: Completed | N20: 45513.088 | O20: 45513.955 | P20: 3.3 | Q20: =TRUE() -> TRUE | R20: =FALSE() -> FALSE | S20: =IF(OR(N20="",O20=""),"N/A",ROUND(((O20-N20)*24),1)) -> 20.8 | T20: =COUNTIF('👤 Customers'!$A:$A, B20) -> 1 | U20: =COUNTIF('🚴 Riders'!A19:A79, C20) -> 1 | V20: =COUNTIF('🏭 Facilities'!A19:A27, D20) -> 0
A21: ORD00020 | B21: CUST0219 | C21: RIDER036 | D21: FAC08 | E21: 45098 | F21: 16:32:07 | G21: Wash & Iron | H21: 3.1 | I21: 299 | J21: 0 | K21: 926.9 | L21: UPI | M21: Cancelled | Q21: =FALSE() -> FALSE | R21: =FALSE() -> FALSE | S21: =IF(OR(N21="",O21=""),"N/A",ROUND(((O21-N21)*24),1)) -> N/A | T21: =COUNTIF('👤 Customers'!$A:$A, B21) -> 1 | U21: =COUNTIF('🚴 Riders'!A20:A80, C21) -> 1 | V21: =COUNTIF('🏭 Facilities'!A20:A28, D21) -> 0
A22: ORD00021 | B22: CUST0276 | C22: RIDER031 | D22: FAC04 | E22: 45448 | F22: 10:43:54 | G22: Wash & Iron | H22: 6.5 | I22: 299 | J22: 0 | K22: 1943.5 | L22: Credit Card | M22: Completed | N22: 45448.527 | O22: 45449.059 | P22: 3.3 | Q22: =FALSE() -> FALSE | R22: =FALSE() -> FALSE | S22: =IF(OR(N22="",O22=""),"N/A",ROUND(((O22-N22)*24),1)) -> 12.8 | T22: =COUNTIF('👤 Customers'!$A:$A, B22) -> 1 | U22: =COUNTIF('🚴 Riders'!A21:A81, C22) -> 1 | V22: =COUNTIF('🏭 Facilities'!A21:A29, D22) -> 0
A23: ORD00022 | B23: CUST0170 | C23: RIDER042 | D23: FAC02 | E23: 45637 | F23: 12:00:41 | G23: Wash & Fold | H23: 4.9 | I23: 199 | J23: 30 | K23: 682.57 | L23: Cash | M23: Cancelled | Q23: =FALSE() -> FALSE | R23: =TRUE() -> TRUE | S23: =IF(OR(N23="",O23=""),"N/A",ROUND(((O23-N23)*24),1)) -> N/A | T23: =COUNTIF('👤 Customers'!$A:$A, B23) -> 1 | U23: =COUNTIF('🚴 Riders'!A22:A82, C23) -> 1 | V23: =COUNTIF('🏭 Facilities'!A22:A30, D23) -> 0
A24: ORD00023 | B24: CUST0390 | C24: RIDER038 | D24: FAC04 | E24: 45489 | F24: 19:14:16 | G24: Dry Clean | H24: 1.4 | I24: 399 | J24: 0 | K24: 558.6 | L24: Cash | M24: Cancelled | Q24: =FALSE() -> FALSE | R24: =FALSE() -> FALSE | S24: =IF(OR(N24="",O24=""),"N/A",ROUND(((O24-N24)*24),1)) -> N/A | T24: =COUNTIF('👤 Customers'!$A:$A, B24) -> 1 | U24: =COUNTIF('🚴 Riders'!A23:A83, C24) -> 1 | V24: =COUNTIF('🏭 Facilities'!A23:A31, D24) -> 0
A25: ORD00024 | B25: CUST0125 | C25: RIDER045 | D25: FAC04 | E25: 45162 | F25: 11:50:03 | G25: Wash & Fold | H25: 2.5 | I25: 199 | J25: 0 | K25: 497.5 | L25: Cash | M25: Delayed | N25: 45162.531 | O25: 45163.612 | Q25: =FALSE() -> FALSE | R25: =FALSE() -> FALSE | S25: =IF(OR(N25="",O25=""),"N/A",ROUND(((O25-N25)*24),1)) -> 26 | T25: =COUNTIF('👤 Customers'!$A:$A, B25) -> 1 | U25: =COUNTIF('🚴 Riders'!A24:A84, C25) -> 1 | V25: =COUNTIF('🏭 Facilities'!A24:A32, D25) -> 0
A26: ORD00025 | B26: CUST0239 | C26: RIDER007 | D26: FAC08 | E26: 45529 | F26: 08:37:35 | G26: Ironing | H26: 3.7 | I26: 149 | J26: 0 | K26: 551.3 | L26: Debit Card | M26: Completed | N26: 45529.425 | O26: 45530.06 | P26: 4.8 | Q26: =FALSE() -> FALSE | R26: =FALSE() -> FALSE | S26: =IF(OR(N26="",O26=""),"N/A",ROUND(((O26-N26)*24),1)) -> 15.2 | T26: =COUNTIF('👤 Customers'!$A:$A, B26) -> 1 | U26: =COUNTIF('🚴 Riders'!A25:A85, C26) -> 0 | V26: =COUNTIF('🏭 Facilities'!A25:A33, D26) -> 0
A27: ORD00026 | B27: CUST0079 | C27: RIDER013 | D27: FAC06 | E27: 45363 | F27: 22:13:15 | G27: Dry Clean | H27: 6.2 | I27: 399 | J27: 0 | K27: 2473.8 | L27: Credit Card | M27: Cancelled | Q27: =FALSE() -> FALSE | R27: =FALSE() -> FALSE | S27: =IF(OR(N27="",O27=""),"N/A",ROUND(((O27-N27)*24),1)) -> N/A | T27: =COUNTIF('👤 Customers'!$A:$A, B27) -> 1 | U27: =COUNTIF('🚴 Riders'!A26:A86, C27) -> 0 | V27: =COUNTIF('🏭 Facilities'!A26:A34, D27) -> 0
A28: ORD00027 | B28: CUST0379 | C28: RIDER032 | D28: FAC08 | E28: 45314 | F28: 19:39:15 | G28: Premium Care | H28: 5.6 | I28: 599 | J28: 10 | K28: 3018.96 | L28: Credit Card | M28: Completed | N28: 45314.951 | O28: 45315.669 | P28: 4.3 | Q28: =FALSE() -> FALSE | R28: =TRUE() -> TRUE | S28: =IF(OR(N28="",O28=""),"N/A",ROUND(((O28-N28)*24),1)) -> 17.3 | T28: =COUNTIF('👤 Customers'!$A:$A, B28) -> 1 | U28: =COUNTIF('🚴 Riders'!A27:A87, C28) -> 1 | V28: =COUNTIF('🏭 Facilities'!A27:A35, D28) -> 0
A29: ORD00028 | B29: CUST0039 | C29: RIDER053 | D29: FAC01 | E29: 45351 | F29: 12:21:43 | G29: Wash & Iron | H29: 2.3 | I29: 299 | J29: 20 | K29: 550.16 | L29: UPI | M29: Delayed | N29: 45351.675 | O29: 45352.43 | Q29: =FALSE() -> FALSE | R29: =FALSE() -> FALSE | S29: =IF(OR(N29="",O29=""),"N/A",ROUND(((O29-N29)*24),1)) -> 18.1 | T29: =COUNTIF('👤 Customers'!$A:$A, B29) -> 1 | U29: =COUNTIF('🚴 Riders'!A28:A88, C29) -> 1 | V29: =COUNTIF('🏭 Facilities'!A28:A36, D29) -> 0
A30: ORD00029 | B30: CUST0479 | C30: RIDER040 | D30: FAC08 | E30: 45106 | F30: 18:13:52 | G30: Wash & Fold | H30: 6 | I30: 199 | J30: 0 | K30: 1194 | L30: Cash | M30: Cancelled | Q30: =TRUE() -> TRUE | R30: =FALSE() -> FALSE | S30: =IF(OR(N30="",O30=""),"N/A",ROUND(((O30-N30)*24),1)) -> N/A | T30: =COUNTIF('👤 Customers'!$A:$A, B30) -> 1 | U30: =COUNTIF('🚴 Riders'!A29:A89, C30) -> 1 | V30: =COUNTIF('🏭 Facilities'!A29:A37, D30) -> 0
A31: ORD00030 | B31: CUST0346 | C31: RIDER028 | D31: FAC03 | E31: 45246 | F31: 11:54:20 | G31: Wash & Fold | H31: 1.1 | I31: 199 | J31: 10 | K31: 197.01 | L31: UPI | M31: Cancelled | Q31: =FALSE() -> FALSE | R31: =FALSE() -> FALSE | S31: =IF(OR(N31="",O31=""),"N/A",ROUND(((O31-N31)*24),1)) -> N/A | T31: =COUNTIF('👤 Customers'!$A:$A, B31) -> 1 | U31: =COUNTIF('🚴 Riders'!A30:A90, C31) -> 0 | V31: =COUNTIF('🏭 Facilities'!A30:A38, D31) -> 0
A32: ORD00031 | B32: CUST0208 | C32: RIDER030 | D32: FAC04 | E32: 45114 | F32: 03:59:04 | G32: Dry Clean | H32: 5.3 | I32: 399 | J32: 0 | K32: 2114.7 | L32: Credit Card | M32: Completed | N32: 45114.226 | O32: 45114.846 | P32: 3.2 | Q32: =FALSE() -> FALSE | R32: =TRUE() -> TRUE | S32: =IF(OR(N32="",O32=""),"N/A",ROUND(((O32-N32)*24),1)) -> 14.9 | T32: =COUNTIF('👤 Customers'!$A:$A, B32) -> 1 | U32: =COUNTIF('🚴 Riders'!A31:A91, C32) -> 1 | V32: =COUNTIF('🏭 Facilities'!A31:A39, D32) -> 0
A33: ORD00032 | B33: CUST0043 | C33: RIDER032 | D33: FAC07 | E33: 45593 | F33: 14:21:52 | G33: Wash & Fold | H33: 1.7 | I33: 199 | J33: 0 | K33: 338.3 | L33: Debit Card | M33: Cancelled | Q33: =FALSE() -> FALSE | R33: =FALSE() -> FALSE | S33: =IF(OR(N33="",O33=""),"N/A",ROUND(((O33-N33)*24),1)) -> N/A | T33: =COUNTIF('👤 Customers'!$A:$A, B33) -> 1 | U33: =COUNTIF('🚴 Riders'!A32:A92, C33) -> 1 | V33: =COUNTIF('🏭 Facilities'!A32:A40, D33) -> 0
A34: ORD00033 | B34: CUST0039 | C34: RIDER044 | D34: FAC05 | E34: 45001 | F34: 01:40:24 | G34: Premium Care | H34: 7.4 | I34: 599 | J34: 0 | K34: 4432.6 | L34: Wallet | M34: Delayed | N34: 45001.219 | O34: 45001.872 | Q34: =FALSE() -> FALSE | R34: =TRUE() -> TRUE | S34: =IF(OR(N34="",O34=""),"N/A",ROUND(((O34-N34)*24),1)) -> 15.7 | T34: =COUNTIF('👤 Customers'!$A:$A, B34) -> 1 | U34: =COUNTIF('🚴 Riders'!A33:A93, C34) -> 1 | V34: =COUNTIF('🏭 Facilities'!A33:A41, D34) -> 0
A35: ORD00034 | B35: CUST0040 | C35: RIDER020 | D35: FAC03 | E35: 45648 | F35: 09:27:35 | G35: Ironing | H35: 1.1 | I35: 149 | J35: 0 | K35: 163.9 | L35: Wallet | M35: Completed | N35: 45648.524 | O35: 45649.384 | P35: 3.1 | Q35: =FALSE() -> FALSE | R35: =FALSE() -> FALSE | S35: =IF(OR(N35="",O35=""),"N/A",ROUND(((O35-N35)*24),1)) -> 20.6 | T35: =COUNTIF('👤 Customers'!$A:$A, B35) -> 1 | U35: =COUNTIF('🚴 Riders'!A34:A94, C35) -> 0 | V35: =COUNTIF('🏭 Facilities'!A34:A42, D35) -> 0
A36: ORD00035 | B36: CUST0382 | C36: RIDER023 | D36: FAC01 | E36: 45623 | F36: 08:27:05 | G36: Premium Care | H36: 3.3 | I36: 599 | J36: 10 | K36: 1779.03 | L36: UPI | M36: Completed | N36: 45623.488 | O36: 45624.303 | P36: 3.6 | Q36: =FALSE() -> FALSE | R36: =FALSE() -> FALSE | S36: =IF(OR(N36="",O36=""),"N/A",ROUND(((O36-N36)*24),1)) -> 19.5 | T36: =COUNTIF('👤 Customers'!$A:$A, B36) -> 1 | U36: =COUNTIF('🚴 Riders'!A35:A95, C36) -> 0 | V36: =COUNTIF('🏭 Facilities'!A35:A43, D36) -> 0
A37: ORD00036 | B37: CUST0252 | C37: RIDER015 | D37: FAC06 | E37: 45524 | F37: 07:18:15 | G37: Premium Care | H37: 7.7 | I37: 599 | J37: 0 | K37: 4612.3 | L37: Wallet | M37: Completed | N37: 45524.329 | O37: 45524.908 | P37: 4.9 | Q37: =FALSE() -> FALSE | R37: =FALSE() -> FALSE | S37: =IF(OR(N37="",O37=""),"N/A",ROUND(((O37-N37)*24),1)) -> 13.9 | T37: =COUNTIF('👤 Customers'!$A:$A, B37) -> 1 | U37: =COUNTIF('🚴 Riders'!A36:A96, C37) -> 0 | V37: =COUNTIF('🏭 Facilities'!A36:A44, D37) -> 0
A38: ORD00037 | B38: CUST0365 | C38: RIDER051 | D38: FAC03 | E38: 45440 | F38: 03:49:01 | G38: Wash & Iron | H38: 1.6 | I38: 299 | J38: 10 | K38: 430.56 | L38: Cash | M38: Completed | N38: 45440.283 | O38: 45440.649 | P38: 3.3 | Q38: =TRUE() -> TRUE | R38: =TRUE() -> TRUE | S38: =IF(OR(N38="",O38=""),"N/A",ROUND(((O38-N38)*24),1)) -> 8.8 | T38: =COUNTIF('👤 Customers'!$A:$A, B38) -> 1 | U38: =COUNTIF('🚴 Riders'!A37:A97, C38) -> 1 | V38: =COUNTIF('🏭 Facilities'!A37:A45, D38) -> 0
A39: ORD00038 | B39: CUST0263 | C39: RIDER027 | D39: FAC02 | E39: 45166 | F39: 10:31:18 | G39: Wash & Iron | H39: 3.5 | I39: 299 | J39: 0 | K39: 1046.5 | L39: UPI | M39: Completed | N39: 45166.472 | O39: 45167.133 | P39: 2.7 | Q39: =FALSE() -> FALSE | R39: =FALSE() -> FALSE | S39: =IF(OR(N39="",O39=""),"N/A",ROUND(((O39-N39)*24),1)) -> 15.9 | T39: =COUNTIF('👤 Customers'!$A:$A, B39) -> 1 | U39: =COUNTIF('🚴 Riders'!A38:A98, C39) -> 0 | V39: =COUNTIF('🏭 Facilities'!A38:A46, D39) -> 0
A40: ORD00039 | B40: CUST0464 | C40: RIDER016 | D40: FAC03 | E40: 45536 | F40: 06:59:51 | G40: Ironing | H40: 7 | I40: 149 | J40: 0 | K40: 1043 | L40: Cash | M40: Completed | N40: 45536.369 | O40: 45536.799 | P40: 2.9 | Q40: =FALSE() -> FALSE | R40: =FALSE() -> FALSE | S40: =IF(OR(N40="",O40=""),"N/A",ROUND(((O40-N40)*24),1)) -> 10.3 | T40: =COUNTIF('👤 Customers'!$A:$A, B40) -> 1 | U40: =COUNTIF('🚴 Riders'!A39:A99, C40) -> 0 | V40: =COUNTIF('🏭 Facilities'!A39:A47, D40) -> 0
...

Sheet 👤 Customers
A1: customer_id | B1: customer_name | C1: email | D1: phone | E1: area | F1: city | G1: signup_date | H1: gender | I1: customer_type
A2: CUST0001 | B2: Vinaya Khurana | C2: wshere@example.org | D2: 910520976424 | E2: Indiranagar | F2: Bangalore | G2: 2024-05-11 | H2: Male | I2: Regular
A3: CUST0002 | B3: Wriddhish Krish | C3: krishasamra@example.net | D3: 288192806 | E3: HSR Layout | F3: Bangalore | G3: 2023-07-10 | H3: Male | I3: Regular
A4: CUST0003 | B4: Onkar Bal | C4: xiti59@example.org | D4: 918215623201 | E4: Hebbal | F4: Bangalore | G4: 2024-06-09 | H4: Other | I4: Regular
A5: CUST0004 | B5: Chandani Pingle | C5: karaliam@example.com | D5: 4011752837 | E5: Koramangala | F5: Bangalore | G5: 2023-11-24 | H5: Male | I5: Regular
A6: CUST0005 | B6: Amrita Patla | C6: harita23@example.net | D6: 9966274843 | E6: Yelahanka | F6: Bangalore | G6: 2023-06-30 | H6: Other | I6: Regular
A7: CUST0006 | B7: Chakradev Sankaran | C7: walionkar@example.com | D7: 7084045507 | E7: Hebbal | F7: Bangalore | G7: 2023-06-04 | H7: Other | I7: Regular
A8: CUST0007 | B8: Rachit Bakshi | C8: zayan28@example.org | D8: 917470542598 | E8: HSR Layout | F8: Bangalore | G8: 2023-11-22 | H8: Female | I8: Regular
A9: CUST0008 | B9: Keya Issac | C9: ozarohan@example.org | D9: 4660628221 | E9: Koramangala | F9: Bangalore | G9: 2024-09-20 | H9: Male | I9: Regular
A10: CUST0009 | B10: Balendra Balakrishnan | C10: upma25@example.com | D10: 741361235 | E10: Jayanagar | F10: Bangalore | G10: 2023-09-22 | H10: Male | I10: Regular
A11: CUST0010 | B11: Harsh Aggarwal | C11: charita81@example.com | D11: 914474583269 | E11: Marathahalli | F11: Bangalore | G11: 2024-08-16 | H11: Male | I11: Regular
A12: CUST0011 | B12: Pahal Kumar | C12: pallavi10@example.com | D12: 919802367003 | E12: Marathahalli | F12: Bangalore | G12: 2023-03-17 | H12: Female | I12: Regular
A13: CUST0012 | B13: Neha Sastry | C13: kotamatthew@example.net | D13: 2541079072 | E13: Koramangala | F13: Bangalore | G13: 2024-09-18 | H13: Other | I13: Regular
... A501: CUST0500 | B501: Hemani Bose | C501: rluthra@example.org | D501: 4273465930 | E501: Jayanagar | F501: Bangalore | G501: 2023-10-17 | H501: Other | I501: Regular

Sheet 🚴 Riders
A1: rider_id | B1: rider_name | C1: phone | D1: area_assigned | E1: vehicle_type | F1: joining_date | G1: rating | H1: total_deliveries | I1: is_active
A2: RIDER001 | B2: Nihal Bail | C2: 915568472739 | D2: Indiranagar | E2: Bicycle | F2: 2022-10-06 | G2: 4.5 | H2: 262 | I2: =TRUE() -> TRUE
A3: RIDER002 | B3: Rachana Prasad | C3: 2982885788 | D3: Hebbal | E3: Bicycle | F3: 2022-08-25 | G3: 3.3 | H3: 1168 | I3: =TRUE() -> TRUE
A4: RIDER003 | B4: Vasatika Pau | C4: 5733475732 | D4: Malleshwaram | E4: Bike | F4: 2023-01-01 | G4: 5 | H4: 1030 | I4: =TRUE() -> TRUE
A5: RIDER004 | B5: Ekani Soni | C5: 6591781079 | D5: Whitefield | E5: Bike | F5: 2022-12-29 | G5: 3.3 | H5: 462 | I5: =TRUE() -> TRUE
A6: RIDER005 | B6: Vidhi Srinivas | C6: 8332341767 | D6: HSR Layout | E6: Bike | F6: 2022-11-04 | G6: 4.9 | H6: 1105 | I6: =TRUE() -> TRUE
A7: RIDER006 | B7: Priya Srivastava | C7: 8624789987 | D7: Yelahanka | E7: Bicycle | F7: 2022-10-11 | G7: 3.3 | H7: 441 | I7: =TRUE() -> TRUE
A8: RIDER007 | B8: Advik Swamy | C8: 917726473054 | D8: Koramangala | E8: Scooter | F8: 2022-11-10 | G8: 3.7 | H8: 803 | I8: =TRUE() -> TRUE
A9: RIDER008 | B9: Ekani Issac | C9: 8703767881 | D9: BTM Layout | E9: Scooter | F9: 2022-12-22 | G9: 4.8 | H9: 841 | I9: =TRUE() -> TRUE
A10: RIDER009 | B10: Nandini Jain | C10: 4970025717 | D10: Whitefield | E10: Bicycle | F10: 2023-01-14 | G10: 3.9 | H10: 1113 | I10: =TRUE() -> TRUE
A11: RIDER010 | B11: Vrishti Johal | C11: 1196557632 | D11: Indiranagar | E11: Scooter | F11: 2022-12-16 | G11: 3.3 | H11: 419 | I11: =TRUE() -> TRUE
A12: RIDER011 | B12: Jason Mane | C12: 3132955696 | D12: Marathahalli | E12: Bike | F12: 2022-08-05 | G12: 3.8 | H12: 655 | I12: =TRUE() -> TRUE
A13: RIDER012 | B13: Kamya Pant | C13: 915292947117 | D13: Rajajinagar | E13: Scooter | F13: 2022-12-17 | G13: 3.5 | H13: 959 | I13: =TRUE() -> TRUE
A14: RIDER013 | B14: Pooja Goda | C14: 1207664960 | D14: Koramangala | E14: Scooter | F14: 2022-11-18 | G14: 4.3 | H14: 940 | I14: =TRUE() -> TRUE
A15: RIDER014 | B15: Priya Shan | C15: 911096972 | D15: Koramangala | E15: Bike | F15: 2022-12-09 | G15: 3.9 | H15: 377 | I15: =FALSE() -> FALSE
A16: RIDER015 | B16: Joshua Mohanty | C16: 4649418950 | D16: Whitefield | E16: Scooter | F16: 2022-12-22 | G16: 3.3 | H16: 187 | I16: =TRUE() -> TRUE
A17: RIDER016 | B17: Yug Bhatt | C17: 915741072706 | D17: Malleshwaram | E17: Bicycle | F17: 2022-11-22 | G17: 3.9 | H17: 116 | I17: =TRUE() -> TRUE
A18: RIDER017 | B18: Bakhshi Narain | C18: 910079088320 | D18: Malleshwaram | E18: Bicycle | F18: 2022-11-26 | G18: 3.9 | H18: 207 | I18: =TRUE() -> TRUE
A19: RIDER018 | B19: Imaran Dey | C19: 916830284600 | D19: Yelahanka | E19: Bicycle | F19: 2022-12-06 | G19: 3.8 | H19: 620 | I19: =TRUE() -> TRUE
A20: RIDER019 | B20: Nisha Srinivas | C20: 5317517468 | D20: Indiranagar | E20: Bike | F20: 2022-09-15 | G20: 4.1 | H20: 842 | I20: =FALSE() -> FALSE
A21: RIDER020 | B21: Zarna Chandra | C21: 910258418881 | D21: Indiranagar | E21: Bicycle | F21: 2022-10-14 | G21: 4.5 | H21: 489 | I21: =FALSE() -> FALSE
A22: RIDER021 | B22: Yutika Kale | C22: 912953477158 | D22: Jayanagar | E22: Scooter | F22: 2023-01-11 | G22: 3.6 | H22: 327 | I22: =TRUE() -> TRUE
A23: RIDER022 | B23: Umang Soni | C23: 9287400839 | D23: Electronic City | E23: Bike | F23: 2022-12-24 | G23: 5 | H23: 704 | I23: =TRUE() -> TRUE
A24: RIDER023 | B24: Azaan More | C24: 912174980349 | D24: Hebbal | E24: Bike | F24: 2023-02-03 | G24: 4.2 | H24: 664 | I24: =TRUE() -> TRUE
A25: RIDER024 | B25: Anmol Rattan | C25: 8790610624 | D25: Hebbal | E25: Scooter | F25: 2022-09-10 | G25: 4.6 | H25: 1091 | I25: =TRUE() -> TRUE
A26: RIDER025 | B26: Baljiwan Baral | C26: 917122779577 | D26: HSR Layout | E26: Bike | F26: 2022-10-04 | G26: 4.6 | H26: 103 | I26: =TRUE() -> TRUE
A27: RIDER026 | B27: Triveni Krishna | C27: 6697434384 | D27: Rajajinagar | E27: Bicycle | F27: 2023-01-02 | G27: 4.6 | H27: 1179 | I27: =TRUE() -> TRUE
A28: RIDER027 | B28: Bachittar Sanghvi | C28: 971322746 | D28: Indiranagar | E28: Bike | F28: 2022-11-02 | G28: 3.9 | H28: 1030 | I28: =TRUE() -> TRUE
A29: RIDER028 | B29: Yashvi Nagy | C29: 6351163847 | D29: BTM Layout | E29: Scooter | F29: 2022-08-02 | G29: 3.4 | H29: 699 | I29: =TRUE() -> TRUE
A30: RIDER029 | B30: Chandran Sanghvi | C30: 911015085537 | D30: Electronic City | E30: Bicycle | F30: 2023-01-21 | G30: 3.8 | H30: 1179 | I30: =TRUE() -> TRUE
A31: RIDER030 | B31: Dhruv Ratta | C31: 1020594712 | D31: Whitefield | E31: Bike | F31: 2022-12-20 | G31: 4.1 | H31: 163 | I31: =TRUE() -> TRUE
A32: RIDER031 | B32: Bhavya Mohan | C32: 5660906124 | D32: Yelahanka | E32: Bike | F32: 2022-10-31 | G32: 3.5 | H32: 710 | I32: =FALSE() -> FALSE
A33: RIDER032 | B33: Tripti Wason | C33: 1726672060 | D33: HSR Layout | E33: Bicycle | F33: 2023-01-22 | G33: 4.8 | H33: 211 | I33: =TRUE() -> TRUE
A34: RIDER033 | B34: Vanya Shetty | C34: 721770913 | D34: Malleshwaram | E34: Scooter | F34: 2022-10-19 | G34: 3.4 | H34: 670 | I34: =TRUE() -> TRUE
A35: RIDER034 | B35: Jhalak Sule | C35: 4050003532 | D35: Indiranagar | E35: Scooter | F35: 2022-09-08 | G35: 4.3 | H35: 365 | I35: =TRUE() -> TRUE
A36: RIDER035 | B36: Ati Palan | C36: 7176498828 | D36: Rajajinagar | E36: Scooter | F36: 2023-02-25 | G36: 3.8 | H36: 134 | I36: =TRUE() -> TRUE
A37: RIDER036 | B37: Dalaja Sodhi | C37: 1094831925 | D37: Koramangala | E37: Bike | F37: 2022-07-22 | G37: 4.9 | H37: 592 | I37: =TRUE() -> TRUE
A38: RIDER037 | B38: Advika Soman | C38: 1284951012 | D38: Rajajinagar | E38: Bicycle | F38: 2022-07-16 | G38: 4.1 | H38: 1167 | I38: =TRUE() -> TRUE
A39: RIDER038 | B39: Chameli Kalita | C39: 4603335483 | D39: Jayanagar | E39: Bicycle | F39: 2022-10-08 | G39: 4.6 | H39: 881 | I39: =TRUE() -> TRUE
A40: RIDER039 | B40: Indrajit Sridhar | C40: 910837900348 | D40: Indiranagar | E40: Scooter | F40: 2022-07-28 | G40: 3.5 | H40: 901 | I40: =TRUE() -> TRUE
...

Sheet 🏭 Facilities
A1: facility_id | B1: facility_name | C1: location | D1: capacity_per_day | E1: operating_since | F1: manager_name | G1: is_operational
A2: FAC01 | B2: Laundryheap Center - Hebbal | C2: Hebbal | D2: 150 | E2: 2022-09-26 | F2: Pranav Dara | G2: =TRUE() -> TRUE
A3: FAC02 | B3: Laundryheap Center - Indiranagar | C3: Indiranagar | D3: 150 | E3: 2022-12-05 | F3: Oviya Raja | G3: =TRUE() -> TRUE
A4: FAC03 | B4: Laundryheap Center - HSR Layout | C4: HSR Layout | D4: 80 | E4: 2022-10-02 | F4: Unnati Garde | G4: =TRUE() -> TRUE
A5: FAC04 | B5: Laundryheap Center - Koramangala | C5: Koramangala | D5: 100 | E5: 2022-08-06 | F5: Azad Krishna | G5: =TRUE() -> TRUE
A6: FAC05 | B6: Laundryheap Center - Electronic City | C6: Electronic City | D6: 150 | E6: 2022-07-24 | F6: Tamanna Dey | G6: =TRUE() -> TRUE
A7: FAC06 | B7: Laundryheap Center - Whitefield | C7: Whitefield | D7: 100 | E7: 2022-06-28 | F7: Yashasvi Chakrabarti | G7: =TRUE() -> TRUE
A8: FAC07 | B8: Laundryheap Center - Rajajinagar | C8: Rajajinagar | D8: 120 | E8: 2022-08-01 | F8: Eesha Madan | G8: =TRUE() -> TRUE
A9: FAC08 | B9: Laundryheap Center - Malleshwaram | C9: Malleshwaram | D9: 120 | E9: 2022-08-25 | F9: Sanaya Karan | G9: =TRUE() -> TRUE
